python main.py mli sdn gdp unemployment
ERROR:root:Exception occurred
Traceback (most recent call last):
  File "C:\Users\Mark\Documents\Research\JCRI\Code\main.py", line 29, in <module>
    main()
  File "C:\Users\Mark\Documents\Research\JCRI\Code\main.py", line 18, in main
    return print(app.app(sys))
  File "C:\Users\Mark\Documents\Research\JCRI\Code\lib\app.py", line 156, in app
    return self.interpreter(country_codes, commands)
  File "C:\Users\Mark\Documents\Research\JCRI\Code\lib\app.py", line 148, in interpreter
    return self.build(country_codes, commands)
  File "C:\Users\Mark\Documents\Research\JCRI\Code\lib\app.py", line 104, in build
    prediction = App.forecast.forecast(data['data'], 10, units)
  File "C:\Users\Mark\Documents\Research\JCRI\Code\lib\forecast.py", line 206, in forecast
    forecast = self.get_forecasts(actuals, horizon, select=forecast)
  File "C:\Users\Mark\Documents\Research\JCRI\Code\lib\forecast.py", line 152, in get_forecasts
    ardl = self.get_ardl(train, horizon)
  File "C:\Users\Mark\Documents\Research\JCRI\Code\lib\forecast.py", line 65, in get_ardl
    results = tsa.ARDL(df, lags=horizon)\
  File "C:\Users\Mark\AppData\Local\Programs\Python\Python39\lib\site-packages\statsmodels\tsa\ardl\model.py", line 328, in __init__
    super().__init__(
  File "C:\Users\Mark\AppData\Local\Programs\Python\Python39\lib\site-packages\statsmodels\tsa\ar_model.py", line 239, in __init__
    self._setup_regressors()
  File "C:\Users\Mark\AppData\Local\Programs\Python\Python39\lib\site-packages\statsmodels\tsa\ardl\model.py", line 415, in _setup_regressors
    self._y = np.empty((self.endog.shape[0] - self._hold_back, 0))
ValueError: negative dimensions are not allowed
